var num = 3
try{
    num = 4
}
catch(err){
    console.log("Error occured!\n"+err)
}
console.log(num)

// What will be the output of the above code?
// -> 3
// -> 4
